<!--
Meta Description: # Atrapalhando Erros com a Função Catch no Mathematica ## Sinopse A função `Catch` em Mathematica é utilizada para lidar com exceções e controlar o fl...
Meta Keywords: catch, throw, que, mathematica, execução
-->

# Atrapalhando Erros com a Função Catch no Mathematica

## Sinopse
A função `Catch` em Mathematica é utilizada para lidar com exceções e controlar o fluxo de execução de um programa, permitindo capturar e processar erros de forma elegante.

## Documentação
A função `Catch` é parte da estrutura de manipulação de exceções em Mathematica. Seu propósito é permitir que o programador capture valores que foram "lançados" por outras partes do código com a função `Throw`. O uso de `Catch` é ideal para situações em que se deseja interromper a execução normal de um bloco de código e lidar com um erro ou uma situação especial.

### Uso
A sintaxe básica para usar `Catch` é:

```mathematica
Catch[expr]
```

- `expr`: A expressão que será executada. Se durante a execução dessa expressão um `Throw` for chamado, o valor fornecido ao `Throw` será retornado pelo `Catch`.

### Detalhes
- `Catch` retorna o valor da expressão `expr` se não ocorrer nenhum `Throw`.
- Se um `Throw` for encontrado, `Catch` interrompe a execução da expressão e retorna o valor fornecido ao `Throw`.
- `Catch` pode ser utilizado em combinações com `Throw` para criar uma estrutura de controle de fluxo mais robusta e previsível.

## Exemplos
### Exemplo Básico
```mathematica
resultado = Catch[1 + Throw[3], _]
```
Saída: `3`

Neste exemplo, a expressão dentro de `Catch` tenta calcular `1 + ...`, mas o `Throw` é chamado, resultando no retorno do valor `3`.

### Exemplo com Condição
```mathematica
resultado = Catch[
  If[5 > 3, Throw["Erro: Condição não satisfeita"], 5]
]
```
Saída: `"Erro: Condição não satisfeita"`

Aqui, a condição é verdadeira, então `Throw` é acionado e a mensagem de erro é retornada.

## Explicação
Um erro comum ao usar `Catch` e `Throw` é esperar que a execução normal do código continue após um `Throw`. Na realidade, `Throw` interrompe a execução e retorna imediatamente para o ponto onde `Catch` foi chamado. Além disso, é importante lembrar que `Catch` pode receber um segundo argumento que especifica um tipo de valor a ser capturado, permitindo uma manipulação mais específica de diferentes tipos de exceções. 

Outra armadilha é esquecer de encapsular a lógica que pode gerar um `Throw` dentro do `Catch`, o que resultaria em um erro não tratado.

## Resumo em Uma Linha
A função `Catch` no Mathematica permite capturar exceções lançadas por `Throw`, facilitando a manipulação de erros e o controle de fluxo de execução.