<!--
Meta Description: # Understanding the "Throw" Function in Mathematica: Exception Handling Made Easy ## Synopsis The `Throw` function in Mathematica is a powerful tool f...
Meta Keywords: throw, catch, error, mathematica, handling
-->

# Understanding the "Throw" Function in Mathematica: Exception Handling Made Easy

## Synopsis
The `Throw` function in Mathematica is a powerful tool for managing control flow, particularly in exception handling scenarios. It allows users to exit from deeply nested constructs and return a value to an associated `Catch` statement.

## Documentation
### Purpose
`Throw` is primarily used in conjunction with `Catch` to facilitate error handling or to break out of loops and other constructs. When a value is thrown using `Throw`, it passes control to the nearest enclosing `Catch`, enabling a clean exit from a computation that may have encountered an unexpected condition.

### Usage
The basic syntax of `Throw` is:
```mathematica
Throw[value, tag]
```
- **value**: The value to be returned to the `Catch`.
- **tag**: An optional argument to identify the type of `Throw`, allowing for more specific control over which `Catch` to respond.

### Details
- The `Catch` function is designed to capture the value thrown by `Throw`, effectively allowing the programmer to define custom control flow.
- If `Throw` is called without an associated `Catch`, Mathematica will throw an error.
- Tags can be used for multiple levels of `Catch`, enabling selective handling of different types of thrown values.

## Examples
### Basic Example
Here is a simple example demonstrating the relationship between `Throw` and `Catch`:
```mathematica
result = Catch[
  If[SomeCondition, Throw[“Error Occurred”]];
  “Normal Execution”
]
```
In this example, if `SomeCondition` is true, the program will exit early, and `result` will hold the value `"Error Occurred"`.

### Using Tags
You can use tags to differentiate between various exceptions:
```mathematica
result = Catch[
  If[condition1, Throw[“First Error”, "error1"]];
  If[condition2, Throw[“Second Error”, "error2"]];
  “Normal Execution”
];

Switch[result,
  "First Error", Print["Caught first error"],
  "Second Error", Print["Caught second error"],
  _, Print["Normal flow"]
]
```
In this case, the `Switch` statement checks which error was caught based on the tag.

## Explanation
### Common Pitfalls
1. **Missing Catch**: If `Throw` is executed without a surrounding `Catch`, it will result in an error. Always ensure that `Throw` is paired with `Catch`.
2. **Scope Issues**: `Throw` only exits to the nearest enclosing `Catch`. Be mindful of nested constructs when using `Throw`.
3. **Tag Misuse**: If tags are not used properly, it may lead to confusion in handling different exceptions. Always document the purpose of each tag for clarity.

### Additional Notes
- `Throw` can be used in various contexts, such as inside loops, functions, and even in more complex structures like `Module` or `Block`.
- It is important to understand that `Throw` and `Catch` are not replacements for traditional error handling; they are meant for program control flow.

## One Line Summary
The `Throw` function in Mathematica provides a mechanism for exiting nested constructs and managing control flow through exception handling in conjunction with `Catch`.